Workbook

Sheet summary
C2: Minimum | D2: Maximum | E2: Average | F2: Standard deviation
B3: Fitness value improvement (%) | C3: =MIN(details!C2:C5250) -> 0.011175138 | D3: =MAX(details!C2:C5250) -> 0.14950787 | E3: =AVERAGE(details!C2:C5250) -> 0.035416624 | F3: =SUMIF(details!H2:H5250,"fitness gain deviation",details!I2:I5250)/COUNTIF(details!H2:H5250,"fitness gain deviation") -> 0.0055301643
B4: Difference (%) | C4: =MIN(details!D2:D5250) -> 2.1818182 | D4: =MAX(details!D2:D5250) -> 25.234672 | E4: =AVERAGE(details!D2:D5250) -> 13.444567 | F4: =SUMIF(details!H2:H5250,"difference deviation",details!I2:I5250)/COUNTIF(details!H2:H5250,"difference deviation") -> 0.16182842
B5: Operands ratio | C5: =MIN(details!E2:E5250) -> 0.12154489 | D5: =MAX(details!E2:E5250) -> 0.99297994 | E5: =AVERAGE(details!E2:E5250) -> 0.32321635 | F5: =SUMIF(details!H2:H5250,"operand ratio deviation",details!I2:I5250)/COUNTIF(details!H2:H5250,"operand ratio deviation") -> 0.0049439787
B6: Solution time (sec) | C6: =MIN(details!F2:F5250) -> 4 | D6: =MAX(details!F2:F5250) -> 1243 | E6: =AVERAGE(details!F2:F5250) -> 45.0256 | F6: =SUMIF(details!H2:H5250,"run time deviation",details!I2:I5250)/COUNTIF(details!H2:H5250,"run time deviation") -> 3.8221786
C8: Count of runs | D8: Count of unique parameter sets
C9: =COUNT(details!C2:C5250) -> 5000 | D9: =C9/20 -> 250
B10: Run time > 6min | C10: =COUNTIF(details!F2:F5250,">360") -> 82 | D10: =C10/20 -> 4.1 | E10: =C10/C9 -> 0.0164

Sheet details
A1: starting fitness | B1: final fitness | C1: fitness gain | D1: difference value | E1: operand ratio | F1: run time
A2: 655.22477 | B2: 688.26431 | C2: =IFERROR((B2/A2)-1,"") -> 0.050424746 | D2: 8.5425701 | E2: 0.34601723 | F2: 16
A3: 653.077 | B3: 683.07388 | C3: =IFERROR((B3/A3)-1,"") -> 0.04593161 | D3: 8.407192 | E3: 0.34028246 | F3: 16
A4: 662.12591 | B4: 686.76795 | C4: =IFERROR((B4/A4)-1,"") -> 0.037216546 | D4: 8.545743 | E4: 0.34138007 | F4: 17
A5: 660.88866 | B5: 683.72529 | C5: =IFERROR((B5/A5)-1,"") -> 0.034554426 | D5: 8.2845056 | E5: 0.32877355 | F5: 16
A6: 655.39958 | B6: 682.37773 | C6: =IFERROR((B6/A6)-1,"") -> 0.0411629 | D6: 8.5383395 | E6: 0.34579465 | F6: 17
A7: 650.26015 | B7: 671.83767 | C7: =IFERROR((B7/A7)-1,"") -> 0.033182909 | D7: 8.291909 | E7: 0.33615851 | F7: 16
A8: 660.74506 | B8: 687.95317 | C8: =IFERROR((B8/A8)-1,"") -> 0.041177934 | D8: 8.5034373 | E8: 0.33989463 | F8: 16
A9: 654.7076 | B9: 690.52966 | C9: =IFERROR((B9/A9)-1,"") -> 0.054714594 | D9: 8.4621893 | E9: 0.34198889 | F9: 17
A10: 657.25078 | B10: 682.72008 | C10: =IFERROR((B10/A10)-1,"") -> 0.038751271 | D10: 8.5848757 | E10: 0.34673412 | F10: 16
A11: 647.48803 | B11: 678.93652 | C11: =IFERROR((B11/A11)-1,"") -> 0.048569996 | D11: 8.3870968 | E11: 0.3427801 | F11: 17
A12: 658.18314 | B12: 682.99168 | C12: =IFERROR((B12/A12)-1,"") -> 0.037692446 | D12: 8.5076679 | E12: 0.34242417 | F12: 16
A13: 664.50156 | B13: 691.2924 | C13: =IFERROR((B13/A13)-1,"") -> 0.040317201 | D13: 8.6451613 | E13: 0.3451996 | F13: 16
... A15: 655.64516 | B15: 686.93861 | C15: =IFERROR((B15/A15)-1,"") -> 0.047729239 | D15: 8.3934426 | E15: 0.33795898 | F15: 16
A16: 655.75026 | B16: 685.62331 | C16: =IFERROR((B16/A16)-1,"") -> 0.045555527 | D16: 8.3807509 | E16: 0.33720437 | F16: 17 | H16: starting fitness deviation | I16: =STDEVP(A2:A21) -> 4.0873493
A17: 652.75754 | B17: 675.52862 | C17: =IFERROR((B17/A17)-1,"") -> 0.034884425 | D17: 8.4843998 | E17: 0.34456779 | F17: 16 | H17: final fitness deviation | I17: =STDEVP(B2:B21) -> 5.0264768
A18: 658.13736 | B18: 689.90947 | C18: =IFERROR((B18/A18)-1,"") -> 0.048275808 | D18: 8.6102591 | E18: 0.34761951 | F18: 16 | H18: fitness gain deviation | I18: =STDEVP(C2:C21) -> 0.0056921803
A19: 657.47451 | B19: 686.64412 | C19: =IFERROR((B19/A19)-1,"") -> 0.044366154 | D19: 8.6208355 | E19: 0.3488276 | F19: 17 | H19: difference deviation | I19: =STDEVP(D2:D21) -> 0.10543994
A20: 654.44849 | B20: 685.64204 | C20: =IFERROR((B20/A20)-1,"") -> 0.047663871 | D20: 8.3818086 | E20: 0.33761776 | F20: 16 | H20: operand ratio deviation | I20: =STDEVP(E2:E21) -> 0.0046872568
A21: 653.11759 | B21: 681.26015 | C21: =IFERROR((B21/A21)-1,"") -> 0.043089576 | D21: 8.4272871 | E21: 0.34119922 | F21: 17 | H21: run time deviation | I21: =STDEVP(F2:F21) -> 0.48989795
C22: =IFERROR((B22/A22)-1,"")
A23: 910.35102 | B23: 963.11837 | C23: =IFERROR((B23/A23)-1,"") -> 0.057963737 | D23: 12.003361 | E23: 0.34600584 | F23: 26
A24: 937.86939 | B24: 966.90612 | C24: =IFERROR((B24/A24)-1,"") -> 0.030960318 | D24: 12.440336 | E24: 0.34850238 | F24: 27
A25: 909.21633 | B25: 965.11837 | C25: =IFERROR((B25/A25)-1,"") -> 0.061483763 | D25: 12.430252 | E25: 0.36260204 | F25: 27
A26: 903.42857 | B26: 956.84898 | C26: =IFERROR((B26/A26)-1,"") -> 0.059130749 | D26: 12.235294 | E26: 0.35798877 | F26: 26
A27: 926.76735 | B27: 960.75918 | C27: =IFERROR((B27/A27)-1,"") -> 0.036677853 | D27: 12.17479 | E27: 0.34340488 | F27: 26
A28: 912.75102 | B28: 951.14286 | C28: =IFERROR((B28/A28)-1,"") -> 0.042061675 | D28: 11.956303 | E28: 0.34252934 | F28: 27
A29: 910.85714 | B29: 961.96735 | C29: =IFERROR((B29/A29)-1,"") -> 0.056112206 | D29: 12.235294 | E29: 0.35461643 | F29: 26
A30: 920.52245 | B30: 975.74694 | C30: =IFERROR((B30/A30)-1,"") -> 0.059992551 | D30: 12.215126 | E30: 0.34844482 | F30: 27
A31: 923.7551 | B31: 966.3102 | C31: =IFERROR((B31/A31)-1,"") -> 0.046067515 | D31: 12.29916 | E31: 0.35017155 | F31: 26
A32: 914.35918 | B32: 974.66939 | C32: =IFERROR((B32/A32)-1,"") -> 0.065958985 | D32: 12.006723 | E32: 0.34350867 | F32: 26
A33: 929.73878 | B33: 970.87347 | C33: =IFERROR((B33/A33)-1,"") -> 0.044243281 | D33: 12.363025 | E33: 0.3500068 | F33: 27
A34: 917.21633 | B34: 960.75918 | C34: =IFERROR((B34/A34)-1,"") -> 0.047472833 | D34: 12.194958 | E34: 0.34982528 | F34: 26
... A36: 906.07347 | B36: 958.75102 | C36: =IFERROR((B36/A36)-1,"") -> 0.058138278 | D36: 11.771429 | E36: 0.33839705 | F36: 27
A37: 929.18367 | B37: 962.27755 | C37: =IFERROR((B37/A37)-1,"") -> 0.035616077 | D37: 12.322689 | E37: 0.34775618 | F37: 26 | H37: starting fitness deviation | I37: =STDEVP(A23:A42) -> 9.1343227
A38: 907.18367 | B38: 949.82041 | C38: =IFERROR((B38/A38)-1,"") -> 0.04699901 | D38: 11.734454 | E38: 0.33648519 | F38: 27 | H38: final fitness deviation | I38: =STDEVP(B23:B42) -> 7.3442335
A39: 911.68163 | B39: 958.73469 | C39: =IFERROR((B39/A39)-1,"") -> 0.051611286 | D39: 11.892437 | E39: 0.34016921 | F39: 25 | H39: fitness gain deviation | I39: =STDEVP(C23:C42) -> 0.0098477148
A40: 920.94694 | B40: 970.66122 | C40: =IFERROR((B40/A40)-1,"") -> 0.053981705 | D40: 12.342857 | E40: 0.35338368 | F40: 26 | H40: difference deviation | I40: =STDEVP(D23:D42) -> 0.20283834
A41: 926.91429 | B41: 971.06939 | C41: =IFERROR((B41/A41)-1,"") -> 0.047636661 | D41: 12.235294 | E41: 0.34601917 | F41: 27 | H41: operand ratio deviation | I41: =STDEVP(E23:E42) -> 0.0062154566
A42: 909.41224 | B42: 967.18367 | C42: =IFERROR((B42/A42)-1,"") -> 0.063526117 | D42: 11.969748 | E42: 0.344827 | F42: 26 | H42: run time deviation | I42: =STDEVP(F23:F42) -> 0.57227616
...
